fun main(){

    try {
        val test = 10/0
    } catch(ex :ArithmeticException) {
        println("Exception")
    }



}